<?xml version="1.0" encoding="utf-8"?>
<!-- This URDF was automatically created by SolidWorks to URDF Exporter! Originally created by Stephen Brawner (brawner@gmail.com) 
     Commit Version: 1.6.0-4-g7f85cfe  Build Version: 1.6.7995.38578
     For more information, please see http://wiki.ros.org/sw_urdf_exporter -->
<robot
  name="GantryAssembly_NoGrasper">
  <link
    name="base_link_gantry">
    <inertial>
      <origin
        xyz="-1.6791E-16 -0.041985 0.017902"
        rpy="0 0 0" />
      <mass
        value="5.7776" />
      <inertia
        ixx="0.32319"
        ixy="1.4897E-16"
        ixz="3.4335E-19"
        iyy="0.27326"
        iyz="1.3637E-17"
        izz="0.59578" />
    </inertial>
    <visual>
      <origin
        xyz="0 0 0"
        rpy="0 0 0" />
      <geometry>
        <mesh
          filename="package://GantryAssembly_NoGrasper/meshes/base_link.STL" />
      </geometry>
      <material
        name="">
        <color
          rgba="0.89804 0.91765 0.92941 1" />
      </material>
    </visual>
    <collision>
      <origin
        xyz="0 0 0"
        rpy="0 0 0" />
      <geometry>
        <mesh
          filename="package://GantryAssembly_NoGrasper/meshes/base_link.STL" />
      </geometry>
    </collision>
  </link>
  <link
    name="LeftUpright">
    <inertial>
      <origin
        xyz="-0.28158 0.35631 -0.041985"
        rpy="0 0 0" />
      <mass
        value="1.4886" />
      <inertia
        ixx="0.056019"
        ixy="3.4202E-18"
        ixz="9.9359E-20"
        iyy="0.00025146"
        iyz="2.1542E-19"
        izz="0.056166" />
    </inertial>
    <visual>
      <origin
        xyz="0 0 0"
        rpy="0 0 0" />
      <geometry>
        <mesh
          filename="package://GantryAssembly_NoGrasper/meshes/LeftUpright.STL" />
      </geometry>
      <material
        name="">
        <color
          rgba="0.89804 0.91765 0.92941 1" />
      </material>
    </visual>
    <collision>
      <origin
        xyz="0 0 0"
        rpy="0 0 0" />
      <geometry>
        <mesh
          filename="package://GantryAssembly_NoGrasper/meshes/LeftUpright.STL" />
      </geometry>
    </collision>
  </link>
  <joint
    name="LeftUprightJoint"
    type="fixed">
    <origin
      xyz="0 -0.041985 0"
      rpy="1.5708 0 0" />
    <parent
      link="base_link_gantry" />
    <child
      link="LeftUpright" />
    <axis
      xyz="0 0 0" />
  </joint>
  <link
    name="ZBar">
    <inertial>
      <origin
        xyz="2.2859E-15 0.010235 -0.041985"
        rpy="0 0 0" />
      <mass
        value="0.92261" />
      <inertia
        ixx="0.00010656"
        ixy="-4.2485E-20"
        ixz="3.0106E-18"
        iyy="0.023961"
        iyz="2.4839E-21"
        izz="0.023919" />
    </inertial>
    <visual>
      <origin
        xyz="0 0 0"
        rpy="0 0 0" />
      <geometry>
        <mesh
          filename="package://GantryAssembly_NoGrasper/meshes/ZBar.STL" />
      </geometry>
      <material
        name="">
        <color
          rgba="0.89412 0.91373 0.92941 1" />
      </material>
    </visual>
    <collision>
      <origin
        xyz="0 0 0"
        rpy="0 0 0" />
      <geometry>
        <mesh
          filename="package://GantryAssembly_NoGrasper/meshes/ZBar.STL" />
      </geometry>
    </collision>
  </link>
  <joint
    name="ZBar_Joint"
    type="prismatic">
    <origin
      xyz="0 0.56296 0"
      rpy="0 0 0" />
    <parent
      link="LeftUpright" />
    <child
      link="ZBar" />
    <axis
      xyz="0 1 0" />
    <limit
      lower="-0.5"
      upper="0"
      effort="0"
      velocity="0" />
  </joint>
  <link
    name="GrasperBase">
    <inertial>
      <origin
        xyz="-0.028605 0.017479 2.9725E-16"
        rpy="0 0 0" />
      <mass
        value="0.26347" />
      <inertia
        ixx="8.1922E-05"
        ixy="-4.7547E-22"
        ixz="-1.6378E-21"
        iyy="0.00012733"
        iyz="-2.3683E-23"
        izz="9.9473E-05" />
    </inertial>
    <visual>
      <origin
        xyz="0 0 0"
        rpy="0 0 0" />
      <geometry>
        <mesh
          filename="package://GantryAssembly_NoGrasper/meshes/GrasperBase.STL" />
      </geometry>
      <material
        name="">
        <color
          rgba="0.89412 0.91373 0.92941 1" />
      </material>
    </visual>
    <collision>
      <origin
        xyz="0 0 0"
        rpy="0 0 0" />
      <geometry>
        <mesh
          filename="package://GantryAssembly_NoGrasper/meshes/GrasperBase.STL" />
      </geometry>
    </collision>
  </link>
  <joint
    name="GrasperBase"
    type="prismatic">
    <origin
      xyz="0.028605 -0.0348 -0.041985"
      rpy="0 0 0" />
    <parent
      link="ZBar" />
    <child
      link="GrasperBase" />
    <axis
      xyz="1 0 0" />
    <limit
      lower="-0.2"
      upper="0.2"
      effort="0"
      velocity="0" />
  </joint>
  <link
    name="RightUpright">
    <inertial>
      <origin
        xyz="0.28158 0.35631 -0.041985"
        rpy="0 0 0" />
      <mass
        value="1.4886" />
      <inertia
        ixx="0.056019"
        ixy="1.2421E-18"
        ixz="-2.2308E-19"
        iyy="0.00025146"
        iyz="1.1323E-18"
        izz="0.056166" />
    </inertial>
    <visual>
      <origin
        xyz="0 0 0"
        rpy="0 0 0" />
      <geometry>
        <mesh
          filename="package://GantryAssembly_NoGrasper/meshes/RightUpright.STL" />
      </geometry>
      <material
        name="">
        <color
          rgba="0.89804 0.91765 0.92941 1" />
      </material>
    </visual>
    <collision>
      <origin
        xyz="0 0 0"
        rpy="0 0 0" />
      <geometry>
        <mesh
          filename="package://GantryAssembly_NoGrasper/meshes/RightUpright.STL" />
      </geometry>
    </collision>
  </link>
  <joint
    name="RightUprightJoint"
    type="fixed">
    <origin
      xyz="0 -0.041985 0"
      rpy="1.5708 0 0" />
    <parent
      link="base_link_gantry" />
    <child
      link="RightUpright" />
    <axis
      xyz="0 0 0" />
    <limit
      lower="-0.5"
      upper="0.5"
      effort="0"
      velocity="0" />
    <dynamics
      damping="0"
      friction="0" />
  </joint>
  <link
    name="BasePlate">
    <inertial>
      <origin
        xyz="6.7623E-17 0.00191 -0.25718"
        rpy="0 0 0" />
      <mass
        value="2.7286" />
      <inertia
        ixx="0.06016"
        ixy="-2.384E-20"
        ixz="-5.0162E-18"
        iyy="0.12031"
        iyz="1.2088E-35"
        izz="0.06016" />
    </inertial>
    <visual>
      <origin
        xyz="0 0 0"
        rpy="0 0 0" />
      <geometry>
        <mesh
          filename="package://GantryAssembly_NoGrasper/meshes/BasePlate.STL" />
      </geometry>
      <material
        name="">
        <color
          rgba="0.89804 0.91765 0.92941 1" />
      </material>
    </visual>
    <collision>
      <origin
        xyz="0 0 0"
        rpy="0 0 0" />
      <geometry>
        <mesh
          filename="package://GantryAssembly_NoGrasper/meshes/BasePlate.STL" />
      </geometry>
    </collision>
  </link>
  <joint
    name="BasePlateJoint"
    type="prismatic">
    <origin
      xyz="0 -0.25718 0.05914"
      rpy="1.5708 0 0" />
    <parent
      link="base_link_gantry" />
    <child
      link="BasePlate" />
    <axis
      xyz="0 0 1" />
    <limit
      lower="-0.3"
      upper="0.3"
      effort="0"
      velocity="0" />
    <dynamics
      damping="0"
      friction="3" />
  </joint>
  <link
    name="ObjectBase">
    <inertial>
      <origin
        xyz="2.3079E-50 0.01 3.0679E-19"
        rpy="0 0 0" />
      <mass
        value="0.03817" />
      <inertia
        ixx="3.4194E-06"
        ixy="-1.1064E-38"
        ixz="5.1616E-54"
        iyy="4.2942E-06"
        iyz="-3.4866E-39"
        izz="3.4194E-06" />
    </inertial>
    <visual>
      <origin
        xyz="0 0 0"
        rpy="0 0 0" />
      <geometry>
        <mesh
          filename="package://GantryAssembly_NoGrasper/meshes/ObjectBase.STL" />
      </geometry>
      <material
        name="">
        <color
          rgba="0.89804 0.91765 0.92941 1" />
      </material>
    </visual>
    <collision>
      <origin
        xyz="0 0 0"
        rpy="0 0 0" />
      <geometry>
        <mesh
          filename="package://GantryAssembly_NoGrasper/meshes/ObjectBase.STL" />
      </geometry>
    </collision>
  </link>
  <joint
    name="ObjectBaseJoint"
    type="fixed">
    <origin
      xyz="0 0.00382 -0.25718"
      rpy="0 0 0" />
    <parent
      link="BasePlate" />
    <child
      link="ObjectBase" />
    <axis
      xyz="0 0 0" />
  </joint>
</robot>